### 문제 상황
- 코틀린 표준 라이브러리에는 runCatching라는 함수가 있다.
- 이 함수는 람다에서 발생하는 모든 Throwable을 잡아내며, 람다 내부에서 별도로 잡지 않거나 밖으로 던지지 않는 이상, 자동으로 Result 객체로 매핑한다.
- 그런데 코루틴 내에서 이 함수를 사용하면, `CancellationException`조차 잡혀버리고 재throw되지 않아서 구조적 동시성에서 코루틴을 취소했을 때 다른 작업들이 동작을 멈추지 않고 그대로 진행되는 문제가 발생할 수 있다.

### 왜 문제가 될까?
- 코틀린 코루틴의 **구조적 동시성(Structured Concurrency)**은, 어떤 코루틴이 CancellationException을 던졌을 때 상위 스코프에서 해당 코루틴과 연관된 모든 하위 작업들이 함께 취소되는 것이 핵심이다.
- 그러나 runCatching이 CancellationException을 계속 안에서 삼켜버리면, 취소 시점에 제대로 예외가 퍼지지 않아 원하는 대로 모든 하위 작업이 중단되지 않을 가능성이 생긴다.

### 해결 방안
아예 새로운 함수를 만들어서 CancellationException만은 잡지 않고 재throw하도록 하는 방법이 제시되었다.

``` kotlin
public inline suspend fun <R> runSuspendCatching(block: () -> R): Result<R> {
    return try {
        Result.success(block())
    } catch(c: CancellationException) {
        throw c
    } catch (e: Throwable) {
        Result.failure(e)
    }
}
```

- CancellationException 발생 시에는 잡지 않고 throw c로 재throw한다.
- 그 외의 일반적인 Throwable만 Result.failure()로 감싸서 반환한다.
- 이렇게 하면, 구조적 동시성을 해치지 않고 예외 처리를 할 수 있다.
- suspend 키워드를 붙여서, 일반 블로킹 코드에서는 사용하지 않도록 하는 것도 요령이다.

### 출처
https://github.com/Kotlin/kotlinx.coroutines/issues/1814
